2015-06-25 18:51:28,161 - tornado.application - ERROR - Uncaught exception POST /meerkat/v1.0.1 (127.0.0.1)
HTTPServerRequest(protocol='https', host='localhost', method='POST', uri='/meerkat/v1.0.1', version='HTTP/1.1', remote_ip='127.0.0.1', headers={'Content-Length': '206', 'Host': 'localhost', 'Content-Type': 'application/json', 'Accept': '*/*', 'User-Agent': 'curl/7.35.0'})
Traceback (most recent call last):
  File "/usr/local/lib/python3.4/dist-packages/tornado/web.py", line 1415, in _execute
    result = yield result
  File "/usr/local/lib/python3.4/dist-packages/tornado/gen.py", line 870, in run
    value = future.result()
  File "/usr/local/lib/python3.4/dist-packages/tornado/concurrent.py", line 215, in result
    raise_exc_info(self._exc_info)
  File "<string>", line 3, in raise_exc_info
  File "/usr/local/lib/python3.4/dist-packages/tornado/gen.py", line 876, in run
    yielded = self.gen.throw(*exc_info)
  File "/home/ubuntu/git/Meerkat/meerkat/web_service/schema.py", line 65, in _wrapper
    output = yield output
  File "/usr/local/lib/python3.4/dist-packages/tornado/gen.py", line 870, in run
    value = future.result()
  File "/usr/local/lib/python3.4/dist-packages/tornado/concurrent.py", line 215, in result
    raise_exc_info(self._exc_info)
  File "<string>", line 3, in raise_exc_info
  File "/usr/local/lib/python3.4/dist-packages/tornado/gen.py", line 876, in run
    yielded = self.gen.throw(*exc_info)
  File "/home/ubuntu/git/Meerkat/meerkat/web_service/api.py", line 53, in post
    results = yield self.thread_pool.submit(self.meerkat.classify, data)
  File "/usr/local/lib/python3.4/dist-packages/tornado/gen.py", line 870, in run
    value = future.result()
  File "/usr/lib/python3.4/concurrent/futures/_base.py", line 395, in result
    return self.__get_result()
  File "/usr/lib/python3.4/concurrent/futures/_base.py", line 354, in __get_result
    raise self._exception
  File "/usr/lib/python3.4/concurrent/futures/thread.py", line 54, in run
    result = self.fn(*self.args, **self.kwargs)
  File "/home/ubuntu/git/Meerkat/meerkat/web_service/web_consumer.py", line 365, in classify
    __bloom_results(data)
NameError: name '_Web_Consumer__bloom_results' is not defined
2015-06-25 18:51:28,163 - tornado.access - ERROR - 500 POST /meerkat/v1.0.1 (127.0.0.1) 5.32ms
2015-06-25 18:53:14,670 - tornado.application - ERROR - Uncaught exception POST /meerkat/v1.0.1 (127.0.0.1)
HTTPServerRequest(protocol='https', host='localhost', method='POST', uri='/meerkat/v1.0.1', version='HTTP/1.1', remote_ip='127.0.0.1', headers={'Content-Length': '206', 'Host': 'localhost', 'User-Agent': 'curl/7.35.0', 'Content-Type': 'application/json', 'Accept': '*/*'})
Traceback (most recent call last):
  File "/usr/local/lib/python3.4/dist-packages/tornado/web.py", line 1415, in _execute
    result = yield result
  File "/usr/local/lib/python3.4/dist-packages/tornado/gen.py", line 870, in run
    value = future.result()
  File "/usr/local/lib/python3.4/dist-packages/tornado/concurrent.py", line 215, in result
    raise_exc_info(self._exc_info)
  File "<string>", line 3, in raise_exc_info
  File "/usr/local/lib/python3.4/dist-packages/tornado/gen.py", line 876, in run
    yielded = self.gen.throw(*exc_info)
  File "/home/ubuntu/git/Meerkat/meerkat/web_service/schema.py", line 65, in _wrapper
    output = yield output
  File "/usr/local/lib/python3.4/dist-packages/tornado/gen.py", line 870, in run
    value = future.result()
  File "/usr/local/lib/python3.4/dist-packages/tornado/concurrent.py", line 215, in result
    raise_exc_info(self._exc_info)
  File "<string>", line 3, in raise_exc_info
  File "/usr/local/lib/python3.4/dist-packages/tornado/gen.py", line 876, in run
    yielded = self.gen.throw(*exc_info)
  File "/home/ubuntu/git/Meerkat/meerkat/web_service/api.py", line 53, in post
    results = yield self.thread_pool.submit(self.meerkat.classify, data)
  File "/usr/local/lib/python3.4/dist-packages/tornado/gen.py", line 870, in run
    value = future.result()
  File "/usr/lib/python3.4/concurrent/futures/_base.py", line 395, in result
    return self.__get_result()
  File "/usr/lib/python3.4/concurrent/futures/_base.py", line 354, in __get_result
    raise self._exception
  File "/usr/lib/python3.4/concurrent/futures/thread.py", line 54, in run
    result = self.fn(*self.args, **self.kwargs)
  File "/home/ubuntu/git/Meerkat/meerkat/web_service/web_consumer.py", line 365, in classify
    bloom_results(data)
NameError: name 'bloom_results' is not defined
2015-06-25 18:53:14,673 - tornado.access - ERROR - 500 POST /meerkat/v1.0.1 (127.0.0.1) 5.39ms
2015-06-25 19:04:35,520 - root - INFO - The bloom filter thinks it's here: 
2015-06-25 19:04:35,520 - root - INFO - None
2015-06-25 19:04:36,306 - tornado.access - INFO - 200 POST /meerkat/v1.0.1 (127.0.0.1) 791.71ms
2015-06-25 21:19:38,072 - root - INFO - The bloom filter thinks it's here: 
2015-06-25 21:19:38,072 - root - INFO - None
2015-06-25 21:19:38,662 - tornado.access - INFO - 200 POST /meerkat/v1.0.1 (127.0.0.1) 592.71ms
